      <?xml version="1.0" encoding="utf-8"?>
      <!-- This URDF was automatically created by SolidWorks to URDF Exporter! Originally created by Stephen Brawner (brawner@gmail.com) 
          Commit Version: 1.6.0-1-g15f4949  Build Version: 1.6.7594.29634
          For more information, please see http://wiki.ros.org/sw_urdf_exporter -->
      <robot
        name="WOLFIE">

        <material name="BLACK">
          <color rgba="0.4 0.4 0.4 1.0"/>
        </material>

          <material name="RED">
          <color rgba="0.8 0.0 0.0 1.0"/>
        </material>

          <material name="GREEN">
          <color rgba="0.0 0.8 0.0 1.0"/>
        </material>

          <material name="BLUE">
          <color rgba="0.0 0.0 0.8 1.0"/>
        </material>

          <material name="YELLOW">
          <color rgba="0.0 0.8 0.8 1.0"/>
        </material>

        <link
          name="TORSO">
          <inertial>
            <origin
              xyz="-0.00018306 -0.00028441 -0.0077566"
              rpy="0 0 0" />
            <mass
              value="1.9221" />
            <inertia
              ixx="0.0021302"
              ixy="-1.4798E-11"
              ixz="1.703E-12"
              iyy="0.0024608"
              iyz="6.5691E-05"
              izz="0.0042499" />
          </inertial>
          <visual>
            <origin
              xyz="0 0 0"
              rpy="0 0 0" />
            <geometry>
              <mesh
                filename="package://WOLFIE/meshes/TORSO.STL" />
            </geometry>
            <material name="BLACK">
            </material>
          </visual>
          <collision>
            <origin
              xyz="0 0 0"
              rpy="0 0 0" />
            <geometry>
              <mesh
                filename="package://WOLFIE/meshes/TORSO.STL" />
            </geometry>
          </collision>
        </link>
        <link
          name="LF_hip">
          <inertial>
            <origin
              xyz="-0.0117702712011137 -1.87277871410742E-05 0.00014483220452377"
              rpy="0 0 0" />
            <mass
              value="0.235842254632568" />
            <inertia
              ixx="7.28685405427517E-05"
              ixy="5.35798223189362E-09"
              ixz="1.5186804814718E-08"
              iyy="3.98747647525235E-05"
              iyz="1.9323207560988E-08"
              izz="3.89069372129281E-05" />
          </inertial>
          <visual>
            <origin
              xyz="0 0 0"
              rpy="0 0 0" />
            <geometry>
              <mesh
                filename="package://WOLFIE/meshes/LF_hip.STL" />
            </geometry>
            <material
              name="BLACK">
            </material>
          </visual>
          <collision>
            <origin
              xyz="0 0 0"
              rpy="0 0 0" />
            <geometry>
              <mesh
                filename="package://WOLFIE/meshes/LF_hip.STL" />
            </geometry>
          </collision>
        </link>
        <joint
          name="LF_hip"
          type="revolute">
          <origin
            xyz="0.1097 0.04497 -0.0016489"
            rpy="-1.5708 0.03665 1.5708" />
          <parent
            link="TORSO" />
          <child
            link="LF_hip" />
          <axis
            xyz="0 0 -1" />
          <limit
            lower="-1.57"
            upper="1.57"
            effort="3"
            velocity="30" />
        </joint>
        <link
          name="LF_thigh">
          <inertial>
            <origin
              xyz="0.0109124090927082 0.000711114703308702 -0.0154662089786918"
              rpy="0 0 0" />
            <mass
              value="0.312294911039796" />
            <inertia
              ixx="5.1589535324927E-05"
              ixy="-2.16657118999102E-08"
              ixz="-3.02895969287288E-07"
              iyy="0.000178216453216"
              iyz="-1.53455069382026E-08"
              izz="0.000223939244494114" />
          </inertial>
          <visual>
            <origin
              xyz="0 0 0"
              rpy="0 0 0" />
            <geometry>
              <mesh
                filename="package://WOLFIE/meshes/LF_thigh.STL" />
            </geometry>
            <material name="BLACK">
            </material>
          </visual>
          <collision>
            <origin
              xyz="0 0 0"
              rpy="0 0 0" />
            <geometry>
              <mesh
                filename="package://WOLFIE/meshes/LF_thigh.STL" />
            </geometry>
          </collision>
        </link>
        <joint
          name="LF_thigh"
          type="revolute">
          <origin
            xyz="0.04495 0 0"
            rpy="1.5708 0 1.5708" />
          <parent
            link="LF_hip" />
          <child
            link="LF_thigh" />
          <axis
            xyz="0 0 1" />
          <limit
            lower="-1.57"
            upper="1.57"
            effort="3"
            velocity="30" />
        </joint>
        <link
          name="LF_tibia">
          <inertial>
            <origin
              xyz="0.0452059251338759 0.000700000145577584 0.000381359253290886"
              rpy="0 0 0" />
            <mass
              value="0.038307750807961" />
            <inertia
              ixx="1.43713163056183E-06"
              ixy="-2.70981133924837E-12"
              ixz="5.31759959095755E-08"
              iyy="2.0678127467915E-05"
              iyz="-4.35379451930662E-13"
              izz="2.14045015823873E-05" />
          </inertial>
          <visual>
            <origin
              xyz="0 0 0"
              rpy="0 0 0" />
            <geometry>
              <mesh
                filename="package://WOLFIE/meshes/LF_tibia.STL" />
            </geometry>
            <material name="BLACK">
            </material>
          </visual>
          <collision>
            <origin
              xyz="0 0 0"
              rpy="0 0 0" />
            <geometry>
              <mesh
                filename="package://WOLFIE/meshes/LF_tibia.STL" />
            </geometry>
          </collision>
        </link>
        <joint
          name="LF_tibia"
          type="revolute">
          <origin
            xyz="0.1 0 0"
            rpy="0 0 0" />
          <parent
            link="LF_thigh" />
          <child
            link="LF_tibia" />
          <axis
            xyz="0 0 1" />
          <limit
            lower="-2.6"
            upper="2.6"
            effort="3"
            velocity="30" />
        </joint>
        <link
          name="RF_hip">
          <inertial>
            <origin
              xyz="-0.0117702712001898 1.87277899122464E-05 -0.000144832207011079"
              rpy="0 0 0" />
            <mass
              value="0.235842254616146" />
            <inertia
              ixx="7.28685405427509E-05"
              ixy="-5.35798223201963E-09"
              ixz="-1.51868048128175E-08"
              iyy="3.98747647525219E-05"
              iyz="1.93232075619372E-08"
              izz="3.89069372129273E-05" />
          </inertial>
          <visual>
            <origin
              xyz="0 0 0"
              rpy="0 0 0" />
            <geometry>
              <mesh
                filename="package://WOLFIE/meshes/RF_hip.STL" />
            </geometry>
            <material name="BLACK">
            </material>
          </visual>
          <collision>
            <origin
              xyz="0 0 0"
              rpy="0 0 0" />
            <geometry>
              <mesh
                filename="package://WOLFIE/meshes/RF_hip.STL" />
            </geometry>
          </collision>
        </link>
        <joint
          name="RF_hip"
          type="revolute">
          <origin
            xyz="0.1097 -0.04497 0.0016489"
            rpy="-1.5708 -0.03665 -1.5708" />
          <parent
            link="TORSO" />
          <child
            link="RF_hip" />
          <axis
            xyz="0 0 1" />
          <limit
            lower="-1.57"
            upper="1.57"
            effort="3"
            velocity="30" />
        </joint>
        <link
          name="RF_thigh">
          <inertial>
            <origin
              xyz="0.0109124090945377 -0.00068888529702886 -0.0154662089762625"
              rpy="0 0 0" />
            <mass
              value="0.312294910999125" />
            <inertia
              ixx="5.15895353249255E-05"
              ixy="-2.16657118759215E-08"
              ixz="-3.02895969284955E-07"
              iyy="0.000178216453215996"
              iyz="-1.53455069409939E-08"
              izz="0.000223939244494112" />
          </inertial>
          <visual>
            <origin
              xyz="0 0 0"
              rpy="0 0 0" />
            <geometry>
              <mesh
                filename="package://WOLFIE/meshes/RF_thigh.STL" />
            </geometry>
            <material name="BLACK">
            </material>
          </visual>
          <collision>
            <origin
              xyz="0 0 0"
              rpy="0 0 0" />
            <geometry>
              <mesh
                filename="package://WOLFIE/meshes/RF_thigh.STL" />
            </geometry>
          </collision>
        </link>
        <joint
          name="RF_thigh"
          type="revolute">
          <origin
            xyz="0.04495 0 0"
            rpy="1.5708 0 1.5708" />
          <parent
            link="RF_hip" />
          <child
            link="RF_thigh" />
          <axis
            xyz="0 0 1" />
          <limit
            lower="-1.57"
            upper="1.57"
            effort="3"
            velocity="30" />
        </joint>
        <link
          name="RF_tibia">
          <inertial>
            <origin
              xyz="0.0452059251338323 -0.000699999854335512 0.000381359253264726"
              rpy="0 0 0" />
            <mass
              value="0.038307750807961" />
            <inertia
              ixx="1.43713163056184E-06"
              ixy="-2.70978092743483E-12"
              ixz="5.31759959101074E-08"
              iyy="2.0678127467915E-05"
              iyz="-4.35379593642106E-13"
              izz="2.14045015823873E-05" />
          </inertial>
          <visual>
            <origin
              xyz="0 0 0"
              rpy="0 0 0" />
            <geometry>
              <mesh
                filename="package://WOLFIE/meshes/RF_tibia.STL" />
            </geometry>
            <material name="BLACK">
            </material>
          </visual>
          <collision>
            <origin
              xyz="0 0 0"
              rpy="0 0 0" />
            <geometry>
              <mesh
                filename="package://WOLFIE/meshes/RF_tibia.STL" />
            </geometry>
          </collision>
        </link>
        <joint
          name="RF_tibia"
          type="revolute">
          <origin
            xyz="0.1 0 0"
            rpy="0 0 0" />
          <parent
            link="RF_thigh" />
          <child
            link="RF_tibia" />
          <axis
            xyz="0 0 1" />
          <limit
            lower="-2.6"
            upper="2.6"
            effort="3"
            velocity="30" />
        </joint>
        <link
          name="LB_hip">
          <inertial>
            <origin
              xyz="-0.0117702712027288 1.87277882404413E-05 -0.00270033638407763"
              rpy="0 0 0" />
            <mass
              value="0.235842254660731" />
            <inertia
              ixx="7.28685405427532E-05"
              ixy="-5.35798223028456E-09"
              ixz="-1.5186804817174E-08"
              iyy="3.98747647525256E-05"
              iyz="1.93232075599247E-08"
              izz="3.89069372129296E-05" />
          </inertial>
          <visual>
            <origin
              xyz="0 0 0"
              rpy="0 0 0" />
            <geometry>
              <mesh
                filename="package://WOLFIE/meshes/LB_hip.STL" />
            </geometry>
            <material name="BLACK">
            </material>
          </visual>
          <collision>
            <origin
              xyz="0 0 0"
              rpy="0 0 0" />
            <geometry>
              <mesh
                filename="package://WOLFIE/meshes/LB_hip.STL" />
            </geometry>
          </collision>
        </link>
        <joint
          name="LB_hip"
          type="revolute">
          <origin
            xyz="-0.11226 0.04497 -0.0016489"
            rpy="-1.5708 0.03665 1.5708" />
          <parent
            link="TORSO" />
          <child
            link="LB_hip" />
          <axis
            xyz="0 0 1" />
          <limit
            lower="-1.57"
            upper="1.57"
            effort="3"
            velocity="30" />
        </joint>
        <link
          name="LB_thigh">
          <inertial>
            <origin
              xyz="0.0109124090868578 -0.00328888529775584 -0.0154662089843313"
              rpy="0 0 0" />
            <mass
              value="0.312294911132881" />
            <inertia
              ixx="5.15895353249343E-05"
              ixy="-2.16657118770603E-08"
              ixz="-3.02895969283487E-07"
              iyy="0.000178216453216005"
              iyz="-1.53455069400177E-08"
              izz="0.000223939244494119" />
          </inertial>
          <visual>
            <origin
              xyz="0 0 0"
              rpy="0 0 0" />
            <geometry>
              <mesh
                filename="package://WOLFIE/meshes/LB_thigh.STL" />
            </geometry>
            <material name="BLACK">
            </material>
          </visual>
          <collision>
            <origin
              xyz="0 0 0"
              rpy="0 0 0" />
            <geometry>
              <mesh
                filename="package://WOLFIE/meshes/LB_thigh.STL" />
            </geometry>
          </collision>
        </link>
        <joint
          name="LB_thigh"
          type="revolute">
          <origin
            xyz="0.04495 0 4.4496E-05"
            rpy="1.5708 0 1.5708" />
          <parent
            link="LB_hip" />
          <child
            link="LB_thigh" />
          <axis
            xyz="0 0 1" />
          <limit
            lower="-1.57"
            upper="1.57"
            effort="3"
            velocity="30" />
        </joint>
        <link
          name="LB_tibia">
          <inertial>
            <origin
              xyz="0.0452059251338311 -0.00329999985437068 0.000381359253263908"
              rpy="0 0 0" />
            <mass
              value="0.0383077508079609" />
            <inertia
              ixx="1.43713163056184E-06"
              ixy="-2.7097801038386E-12"
              ixz="5.31759959103733E-08"
              iyy="2.0678127467915E-05"
              iyz="-4.35379579532157E-13"
              izz="2.14045015823873E-05" />
          </inertial>
          <visual>
            <origin
              xyz="0 0 0"
              rpy="0 0 0" />
            <geometry>
              <mesh
                filename="package://WOLFIE/meshes/LB_tibia.STL" />
            </geometry>
            <material name="BLACK">
            </material>
          </visual>
          <collision>
            <origin
              xyz="0 0 0"
              rpy="0 0 0" />
            <geometry>
              <mesh
                filename="package://WOLFIE/meshes/LB_tibia.STL" />
            </geometry>
          </collision>
        </link>
        <joint
          name="LB_tibia"
          type="revolute">
          <origin
            xyz="0.1 0 0"
            rpy="0 0 0" />
          <parent
            link="LB_thigh" />
          <child
            link="LB_tibia" />
          <axis
            xyz="0 0 1" />
          <limit
            lower="-2.6"
            upper="2.6"
            effort="3"
            velocity="30" />
        </joint>
        <link
          name="RB_hip">
          <inertial>
            <origin
              xyz="-0.0117702712001898 1.87277899122464E-05 -0.000144832207011079"
              rpy="0 0 0" />
            <mass
              value="0.235842254616146" />
            <inertia
              ixx="7.28685405427509E-05"
              ixy="5.35798223201963E-09"
              ixz="-1.51868048128175E-08"
              iyy="3.98747647525219E-05"
              iyz="1.93232075619372E-08"
              izz="3.89069372129273E-05" />
          </inertial>
          <visual>
            <origin
              xyz="0 0 0"
              rpy="0 0 0" />
            <geometry>
              <mesh
                filename="package://WOLFIE/meshes/RB_hip.STL" />
            </geometry>
            <material name="BLACK">
            </material>
          </visual>
          <collision>
            <origin
              xyz="0 0 0"
              rpy="0 0 0" />
            <geometry>
              <mesh
                filename="package://WOLFIE/meshes/RB_hip.STL" />
            </geometry>
          </collision>
        </link>
        <joint
          name="RB_hip"
          type="revolute">
          <origin
            xyz="-0.11226 -0.04497 0.0016489"
            rpy="-1.5708 -0.03665 -1.5708" />
          <parent
            link="TORSO" />
          <child
            link="RB_hip" />
          <axis
            xyz="0 0 -1" />
          <limit
            lower="-1.57"
            upper="1.57"
            effort="3"
            velocity="30" />
        </joint>
        <link
          name="RB_thigh">
          <inertial>
            <origin
              xyz="0.0109124090871409 0.00331111470217332 -0.0154662089860592"
              rpy="0 0 0" />
            <mass
              value="0.312294911161812" />
            <inertia
              ixx="5.1589535324937E-05"
              ixy="-2.16657118827029E-08"
              ixz="-3.02895969289817E-07"
              iyy="0.000178216453216007"
              iyz="-1.53455069363805E-08"
              izz="0.000223939244494121" />
          </inertial>
          <visual>
            <origin
              xyz="0 0 0"
              rpy="0 0 0" />
            <geometry>
              <mesh
                filename="package://WOLFIE/meshes/RB_thigh.STL" />
            </geometry>
            <material name="BLACK">
            </material>
          </visual>
          <collision>
            <origin
              xyz="0 0 0"
              rpy="0 0 0" />
            <geometry>
              <mesh
                filename="package://WOLFIE/meshes/RB_thigh.STL" />
            </geometry>
          </collision>
        </link>
        <joint
          name="RB_thigh"
          type="revolute">
          <origin
            xyz="0.04495 0 -4.4496E-05"
            rpy="1.5708 0 1.5708" />
          <parent
            link="RB_hip" />
          <child
            link="RB_thigh" />
          <axis
            xyz="0 0 1" />
          <limit
            lower="-2"
            upper="2"
            effort="3"
            velocity="30" />
        </joint>
        <link
          name="RB_tibia">
          <inertial>
            <origin
              xyz="0.0452059251338691 0.00330000014550186 0.000381359253273608"
              rpy="0 0 0" />
            <mass
              value="0.038307750807961" />
            <inertia
              ixx="1.43713163056184E-06"
              ixy="-2.70978093650014E-12"
              ixz="5.31759959101059E-08"
              iyy="2.0678127467915E-05"
              iyz="-4.35379593827211E-13"
              izz="2.14045015823873E-05" />
          </inertial>
          <visual>
            <origin
              xyz="0 0 0"
              rpy="0 0 0" />
            <geometry>
              <mesh
                filename="package://WOLFIE/meshes/RB_tibia.STL" />
            </geometry>
            <material name="BLACK">
            </material>
          </visual>
          <collision>
            <origin
              xyz="0 0 0"
              rpy="0 0 0" />
            <geometry>
              <mesh
                filename="package://WOLFIE/meshes/RB_tibia.STL" />
            </geometry>
          </collision>
        </link>
        <joint
          name="RB_tibia"
          type="revolute">
          <origin
            xyz="0.1 0 0"
            rpy="0 0 0" />
          <parent
            link="RB_thigh" />
          <child
            link="RB_tibia" />
          <axis
            xyz="0 0 1" />
          <limit
            lower="-2.6"
            upper="2.6"
            effort="3"
            velocity="30" />
        </joint>
      </robot>
